Workbook

Sheet Planilha1
A1: CODMUNRES | B1: MUNICIPIO | C1: UF
A2: 355030 | B2: =VLOOKUP(A2,Planilha2!$A$2:$C$5566,3,0) -> SÃO PAULO | C2: =VLOOKUP(A2,Planilha2!$A$2:$D$5566,4,0) -> SP
A3: 120030 | B3: =VLOOKUP(A3,Planilha2!$A$2:$C$5566,3,0) -> FEIJÓ | C3: =VLOOKUP(A3,Planilha2!$A$2:$D$5566,4,0) -> AC
A4: 251600 | B4: =VLOOKUP(A4,Planilha2!$A$2:$C$5566,3,0) -> SOLÂNEA | C4: =VLOOKUP(A4,Planilha2!$A$2:$D$5566,4,0) -> PB
A5: 260290 | B5: =VLOOKUP(A5,Planilha2!$A$2:$C$5566,3,0) -> CABO DE SANTO AGOSTINHO | C5: =VLOOKUP(A5,Planilha2!$A$2:$D$5566,4,0) -> PE
A6: 230210 | B6: =VLOOKUP(A6,Planilha2!$A$2:$C$5566,3,0) -> BATURITÉ | C6: =VLOOKUP(A6,Planilha2!$A$2:$D$5566,4,0) -> CE
A7: 221100 | B7: =VLOOKUP(A7,Planilha2!$A$2:$C$5566,3,0) -> TERESINA | C7: =VLOOKUP(A7,Planilha2!$A$2:$D$5566,4,0) -> PI
A8: 171330 | B8: =VLOOKUP(A8,Planilha2!$A$2:$C$5566,3,0) -> MIRANORTE | C8: =VLOOKUP(A8,Planilha2!$A$2:$D$5566,4,0) -> TO
A9: 110010 | B9: =VLOOKUP(A9,Planilha2!$A$2:$C$5566,3,0) -> GUAJARÁ-MIRIM | C9: =VLOOKUP(A9,Planilha2!$A$2:$D$5566,4,0) -> RO
A10: 140010 | B10: =VLOOKUP(A10,Planilha2!$A$2:$C$5566,3,0) -> BOA VISTA | C10: =VLOOKUP(A10,Planilha2!$A$2:$D$5566,4,0) -> RR
A11: 320240 | B11: =VLOOKUP(A11,Planilha2!$A$2:$C$5566,3,0) -> GUARAPARI | C11: =VLOOKUP(A11,Planilha2!$A$2:$D$5566,4,0) -> ES
A12: 320380 | B12: =VLOOKUP(A12,Planilha2!$A$2:$C$5566,3,0) -> MUQUI | C12: =VLOOKUP(A12,Planilha2!$A$2:$D$5566,4,0) -> ES
A13: 352420 | B13: =VLOOKUP(A13,Planilha2!$A$2:$C$5566,3,0) -> JABORANDI | C13: =VLOOKUP(A13,Planilha2!$A$2:$D$5566,4,0) -> SP
... A92: 110028 | B92: =VLOOKUP(A92,Planilha2!$A$2:$C$5566,3,0) -> ROLIM DE MOURA | C92: =VLOOKUP(A92,Planilha2!$A$2:$D$5566,4,0) -> RO
A93: 110001 | B93: =VLOOKUP(A93,[1]IBGE!A$2:B$27,2,0) -> Alta Floresta D'Oeste | C93: =VLOOKUP(A93,[1]IBGE!A$2:C$27,3,0) -> RO
A94: 110008 | B94: =VLOOKUP(A94,Planilha2!$A$2:$C$5566,3,0) -> COSTA MARQUES | C94: =VLOOKUP(A94,Planilha2!$A$2:$D$5566,4,0) -> RO
A95: 130260 | B95: =VLOOKUP(A95,Planilha2!$A$2:$C$5566,3,0) -> MANAUS | C95: =VLOOKUP(A95,Planilha2!$A$2:$D$5566,4,0) -> AM
A96: 130010 | B96: =VLOOKUP(A96,Planilha2!$A$2:$C$5566,3,0) -> ANORI | C96: =VLOOKUP(A96,Planilha2!$A$2:$D$5566,4,0) -> AM
A97: 130360 | B97: =VLOOKUP(A97,Planilha2!$A$2:$C$5566,3,0) -> SANTA ISABEL DO RIO NEGRO | C97: =VLOOKUP(A97,Planilha2!$A$2:$D$5566,4,0) -> AM
A98: 130120 | B98: =VLOOKUP(A98,Planilha2!$A$2:$C$5566,3,0) -> COARI | C98: =VLOOKUP(A98,Planilha2!$A$2:$D$5566,4,0) -> AM
A99: 130180 | B99: =VLOOKUP(A99,Planilha2!$A$2:$C$5566,3,0) -> IPIXUNA | C99: =VLOOKUP(A99,Planilha2!$A$2:$D$5566,4,0) -> AM
A100: 130390 | B100: =VLOOKUP(A100,Planilha2!$A$2:$C$5566,3,0) -> SÃO PAULO DE OLIVENÇA | C100: =VLOOKUP(A100,Planilha2!$A$2:$D$5566,4,0) -> AM
A101: 130014 | B101: =VLOOKUP(A101,Planilha2!$A$2:$C$5566,3,0) -> APUÍ | C101: =VLOOKUP(A101,Planilha2!$A$2:$D$5566,4,0) -> AM
A102: 130420 | B102: =VLOOKUP(A102,Planilha2!$A$2:$C$5566,3,0) -> TEFÉ | C102: =VLOOKUP(A102,Planilha2!$A$2:$D$5566,4,0) -> AM
A103: 130320 | B103: =VLOOKUP(A103,Planilha2!$A$2:$C$5566,3,0) -> NOVO AIRÃO | C103: =VLOOKUP(A103,Planilha2!$A$2:$D$5566,4,0) -> AM
A104: 130190 | B104: =VLOOKUP(A104,Planilha2!$A$2:$C$5566,3,0) -> ITACOATIARA | C104: =VLOOKUP(A104,Planilha2!$A$2:$D$5566,4,0) -> AM
A105: 130250 | B105: =VLOOKUP(A105,Planilha2!$A$2:$C$5566,3,0) -> MANACAPURU | C105: =VLOOKUP(A105,Planilha2!$A$2:$D$5566,4,0) -> AM
... A986: 290405 | B986: =VLOOKUP(A986,Planilha2!$A$2:$C$5566,3,0) -> BONITO | C986: =VLOOKUP(A986,Planilha2!$A$2:$D$5566,4,0) -> BA
A987: 290000 | B987: =VLOOKUP(A987,[1]IBGE!A$2:B$27,2,0) -> - | C987: =VLOOKUP(A987,[1]IBGE!A$2:C$27,3,0) -> BA
A988: 291780 | B988: =VLOOKUP(A988,Planilha2!$A$2:$C$5566,3,0) -> JAGUARIPE | C988: =VLOOKUP(A988,Planilha2!$A$2:$D$5566,4,0) -> BA
A989: 291005 | B989: =VLOOKUP(A989,Planilha2!$A$2:$C$5566,3,0) -> DIAS D`ÁVILA | C989: =VLOOKUP(A989,Planilha2!$A$2:$D$5566,4,0) -> BA
A990: 290930 | B990: =VLOOKUP(A990,Planilha2!$A$2:$C$5566,3,0) -> CORRENTINA | C990: =VLOOKUP(A990,Planilha2!$A$2:$D$5566,4,0) -> BA
A991: 290400 | B991: =VLOOKUP(A991,Planilha2!$A$2:$C$5566,3,0) -> BONINAL | C991: =VLOOKUP(A991,Planilha2!$A$2:$D$5566,4,0) -> BA
A992: 292590 | B992: =VLOOKUP(A992,Planilha2!$A$2:$C$5566,3,0) -> QUIJINGUE | C992: =VLOOKUP(A992,Planilha2!$A$2:$D$5566,4,0) -> BA
A993: 292210 | B993: =VLOOKUP(A993,Planilha2!$A$2:$C$5566,3,0) -> MUNDO NOVO | C993: =VLOOKUP(A993,Planilha2!$A$2:$D$5566,4,0) -> BA
A994: 292430 | B994: =VLOOKUP(A994,Planilha2!$A$2:$C$5566,3,0) -> PIATÃ | C994: =VLOOKUP(A994,Planilha2!$A$2:$D$5566,4,0) -> BA
A995: 292480 | B995: =VLOOKUP(A995,Planilha2!$A$2:$C$5566,3,0) -> PIRITIBA | C995: =VLOOKUP(A995,Planilha2!$A$2:$D$5566,4,0) -> BA
A996: 292140 | B996: =VLOOKUP(A996,Planilha2!$A$2:$C$5566,3,0) -> MIRANGABA | C996: =VLOOKUP(A996,Planilha2!$A$2:$D$5566,4,0) -> BA
A997: 291750 | B997: =VLOOKUP(A997,Planilha2!$A$2:$C$5566,3,0) -> JACOBINA | C997: =VLOOKUP(A997,Planilha2!$A$2:$D$5566,4,0) -> BA
A998: 293120 | B998: =VLOOKUP(A998,Planilha2!$A$2:$C$5566,3,0) -> TAPEROÁ | C998: =VLOOKUP(A998,Planilha2!$A$2:$D$5566,4,0) -> BA
...

Sheet Planilha2
A1: iMunicipio_IBGE | B1: iMunicipio_SIACI | C1: vMunicipio | D1: cSG_UF | E1: vRegiao | F1: iPopulacao_Total | G1: iPorte_Municipio | H1: vRegiao_Metropolitana | I1: mLatitude | J1: mLongitude | K1: iAltitude | L1: iArea | M1: IDH
A2: 110002 | B2: 3026 | C2: ARIQUEMES | D2: RO | E2: ARIQUEMES | F2: 82388 | G2: 2 | H2: NULL | I2: -991300 | J2: -6304100 | K2: 142 | L2: 4426 | M2: NULL
A3: 110003 | B3: 8001 | C3: CABIXI | D3: RO | E3: COLORADO DO OESTE | F3: 6575 | G3: 1 | H3: NULL | I3: -1349200 | J3: -6054500 | K3: 230 | L3: 1314 | M3: NULL
A4: 110004 | B4: 3042 | C4: CACOAL | D4: RO | E4: CACOAL | F4: 76155 | G4: 2 | H4: NULL | I4: -1143800 | J4: -6144800 | K4: 200 | L4: 3792 | M4: NULL
A5: 110005 | B5: 12416 | C5: CEREJEIRAS | D5: RO | E5: COLORADO DO OESTE | F5: 16290 | G5: 1 | H5: NULL | I5: -1318900 | J5: -6081200 | K5: 277 | L5: 2783 | M5: NULL
A6: 110006 | B6: 3077 | C6: COLORADO DO OESTE | D6: RO | E6: COLORADO DO OESTE | F6: 17644 | G6: 1 | H6: NULL | I6: -1311700 | J6: -6054200 | K6: 460 | L6: 1451 | M6: NULL
A7: 110007 | B7: 49042 | C7: CORUMBIARA | D7: RO | E7: COLORADO DO OESTE | F7: 9476 | G7: 1 | H7: NULL | I7: -1296200 | J7: -6088700 | K7: 340 | L7: 3060 | M7: NULL
A8: 110008 | B8: 3085 | C8: COSTA MARQUES | D8: RO | E8: GUAJARA-MIRIM | F8: 13664 | G8: 1 | H8: NULL | I8: -1244500 | J8: -6422700 | K8: 140 | L8: 12722 | M8: NULL
A9: 110009 | B9: 3093 | C9: ESPIGÃO D`OESTE | D9: RO | E9: CACOAL | F9: 27867 | G9: 1 | H9: NULL | I9: -1152500 | J9: -6101300 | K9: 270 | L9: 4518 | M9: NULL
A10: 110010 | B10: 3018 | C10: GUAJARÁ-MIRIM | D10: RO | E10: GUAJARA-MIRIM | F10: 39451 | G10: 1 | H10: NULL | I10: -1078300 | J10: -6533900 | K10: 128 | L10: 24855 | M10: NULL
A11: 110011 | B11: 45306 | C11: JARU | D11: RO | E11: JI-PARANA | F11: 52453 | G11: 2 | H11: NULL | I11: -1043900 | J11: -6246600 | K11: 124 | L11: 2944 | M11: NULL
A12: 110012 | B12: 3034 | C12: JI-PARANÁ | D12: RO | E12: JI-PARANA | F12: 107679 | G12: 3 | H12: NULL | I12: -1088200 | J12: -6194400 | K12: 170 | L12: 6896 | M12: NULL
A13: 110013 | B13: 10685 | C13: MACHADINHO D`OESTE | D13: RO | E13: ARIQUEMES | F13: 31475 | G13: 1 | H13: NULL | I13: -944400 | J13: -6198100 | K13: 102 | L13: 8509 | M13: NULL
... A81: 130030 | B81: 3549 | C81: AUTAZES | D81: AM | E81: MANAUS | F81: 29907 | G81: 4 | H81: RM MANAUS | I81: -358000 | J81: -5913100 | K81: 36 | L81: 7599 | M81: NULL
A82: 130040 | B82: 3557 | C82: BARCELOS | D82: AM | E82: RIO NEGRO | F82: 24567 | G82: 1 | H82: NULL | I82: -0.97500 | J82: -6292400 | K82: 47 | L82: 122475 | M82: NULL
A83: 130050 | B83: 3565 | C83: BARREIRINHA | D83: AM | E83: PARINTINS | F83: 26645 | G83: 1 | H83: NULL | I83: -279300 | J83: -5707000 | K83: 19 | L83: 5750 | M83: NULL
A84: 130060 | B84: 3573 | C84: BENJAMIN CONSTANT | D84: AM | E84: ALTO SOLIMOES | F84: 29268 | G84: 1 | H84: NULL | I84: -438300 | J84: -7003100 | K84: 65 | L84: 8793 | M84: NULL
A85: 130063 | B85: 3131 | C85: BERURI | D85: AM | E85: COARI | F85: 13809 | G85: 1 | H85: NULL | I85: -389800 | J85: -6137300 | K85: 35 | L85: 17251 | M85: NULL
A86: 130068 | B86: 3158 | C86: BOA VISTA DO RAMOS | D86: AM | E86: PARINTINS | F86: 13138 | G86: 1 | H86: NULL | I86: -297000 | J86: -5759000 | K86: 32 | L86: 2586 | M86: NULL
A87: 130070 | B87: 3581 | C87: BOCA DO ACRE | D87: AM | E87: BOCA DO ACRE | F87: 29818 | G87: 1 | H87: NULL | I87: -875200 | J87: -6739800 | K87: 116 | L87: 22348 | M87: NULL
A88: 130080 | B88: 3590 | C88: BORBA | D88: AM | E88: MADEIRA | F88: 31098 | G88: 1 | H88: NULL | I88: -438800 | J88: -5959400 | K88: 45 | L88: 44251 | M88: NULL
A89: 130083 | B89: 3166 | C89: CAAPIRANGA | D89: AM | E89: COARI | F89: 10547 | G89: 1 | H89: NULL | I89: -332800 | J89: -6120900 | K89: 32 | L89: 9456 | M89: NULL
A90: 130090 | B90: 3603 | C90: CANUTAMA | D90: AM | E90: PURUS | F90: 11463 | G90: 1 | H90: NULL | I90: -653400 | J90: -6438300 | K90: 55 | L90: 29819 | M90: NULL
A91: 130100 | B91: 3611 | C91: CARAUARI | D91: AM | E91: JURUA | F91: 25110 | G91: 1 | H91: NULL | I91: -488300 | J91: -6689600 | K91: 87 | L91: 25767 | M91: NULL
A92: 130110 | B92: 3620 | C92: CAREIRO | D92: AM | E92: MANAUS | F92: 31070 | G92: 4 | H92: RM MANAUS | I92: -376800 | J92: -6036900 | K92: 27 | L92: 6091 | M92: NULL
A93: 130115 | B93: 27383 | C93: CAREIRO DA VÁRZEA | D93: AM | E93: MANAUS | F93: 23023 | G93: 4 | H93: RM MANAUS | I93: -322100 | J93: -5982600 | K93: 25 | L93: 2631 | M93: NULL
A94: 130120 | B94: 3638 | C94: COARI | D94: AM | E94: COARI | F94: 65222 | G94: 2 | H94: NULL | I94: -408500 | J94: -6314100 | K94: 10 | L94: 57921 | M94: NULL
... A123: 130356 | B123: 4880 | C123: RIO PRETO DA EVA | D123: AM | E123: RIO PRETO DA EVA | F123: 24858 | G123: 4 | H123: RM MANAUS | I123: -269900 | J123: -5970000 | K123: 47 | L123: 5813 | M123: NULL
A124: 130360 | B124: 3697 | C124: SANTA ISABEL DO RIO NEGRO | D124: AM | E124: RIO NEGRO | F124: 16921 | G124: 1 | H124: NULL | I124: -0.41400 | J124: -6501900 | K124: 60 | L124: 62846 | M124: NULL
A125: 130370 | B125: 3867 | C125: SANTO ANTÔNIO DO IÇÁ | D125: AM | E125: ALTO SOLIMOES | F125: 29249 | G125: 1 | H125: NULL | I125: -310200 | J125: -6794000 | K125: 91 | L125: 12307 | M125: NULL
A126: 130380 | B126: 3875 | C126: SÃO GABRIEL DA CACHOEIRA | D126: AM | E126: RIO NEGRO | F126: 39129 | G126: 1 | H126: NULL | I126: -0.13000 | J126: -6708900 | K126: 132 | L126: 109184 | M126: NULL
A127: 130390 | B127: 3883 | C127: SÃO PAULO DE OLIVENÇA | D127: AM | E127: ALTO SOLIMOES | F127: 30727 | G127: 1 | H127: NULL | I127: -337800 | J127: -6887300 | K127: 102 | L127: 19745 | M127: NULL
A128: 130395 | B128: 4898 | C128: SÃO SEBASTIÃO DO UATUMÃ | D128: AM | E128: PARINTINS | F128: 8731 | G128: 1 | H128: NULL | I128: -257200 | J128: -5787100 | K128: 24 | L128: 10741 | M128: NULL
A129: 130400 | B129: 3891 | C129: SILVES | D129: AM | E129: ITACOATIARA | F129: 8211 | G129: 4 | H129: RM MANAUS | I129: -283900 | J129: -5820900 | K129: 46 | L129: 3748 | M129: NULL
A130: 130406 | B130: 4910 | C130: TABATINGA | D130: AM | E130: ALTO SOLIMOES | F130: 45293 | G130: 1 | H130: NULL | I130: -425300 | J130: -6993800 | K130: 60 | L130: 3225 | M130: NULL
A131: 130410 | B131: 3905 | C131: TAPAUÁ | D131: AM | E131: PURUS | F131: 19453 | G131: 1 | H131: NULL | I131: -562800 | J131: -6318300 | K131: 54 | L131: 89324 | M131: NULL
A132: 130420 | B132: 3913 | C132: TEFÉ | D132: AM | E132: TEFE | F132: 62920 | G132: 2 | H132: NULL | I132: -335400 | J132: -6471100 | K132: 75 | L132: 23704 | M132: NULL
A133: 130423 | B133: 4936 | C133: TONANTINS | D133: AM | E133: ALTO SOLIMOES | F133: 19090 | G133: 1 | H133: NULL | I133: -287300 | J133: -6780200 | K133: 55 | L133: 6432 | M133: NULL
A134: 130426 | B134: 4944 | C134: UARINI | D134: AM | E134: TEFE | F134: 9859 | G134: 1 | H134: NULL | I134: -299000 | J134: -6510800 | K134: 60 | L134: 10246 | M134: NULL
A135: 130430 | B135: 3921 | C135: URUCARÁ | D135: AM | E135: PARINTINS | F135: 15716 | G135: 1 | H135: NULL | I135: -253600 | J135: -5776000 | K135: 26 | L135: 27904 | M135: NULL
...
